Workbook

Sheet Phases
A1: BitForge: Open-Source Tool Map by Phase (solo schedule)
A2: Blue = editable inputs. Work item counts and progress are formulas driven by the Tool Map status column.
A4: Phase | B4: Name | C4: Start | D4: End | E4: Planned hours | F4: Work items | G4: Done | H4: In progress | I4: % done
A5: P0 | B5: Setup and specs (front-end only) | C5: 46300 | D5: 46313 | E5: 50 | F5: =COUNTIF('Tool Map'!$B:$B,A5) -> 9 | G5: =COUNTIFS('Tool Map'!$B:$B,A5,'Tool Map'!$I:$I,"Done") -> 0 | H5: =COUNTIFS('Tool Map'!$B:$B,A5,'Tool Map'!$I:$I,"In progress") -> 0 | I5: =IF(F5=0,0,G5/F5) -> 0
A6: P1 | B6: Single-lane core and IHP synthesis | C6: 46314 | D6: 46334 | E6: 75 | F6: =COUNTIF('Tool Map'!$B:$B,A6) -> 14 | G6: =COUNTIFS('Tool Map'!$B:$B,A6,'Tool Map'!$I:$I,"Done") -> 0 | H6: =COUNTIFS('Tool Map'!$B:$B,A6,'Tool Map'!$I:$I,"In progress") -> 0 | I6: =IF(F6=0,0,G6/F6) -> 0
A7: P2 | B7: Two lanes and host interface (front-end) | C7: 46335 | D7: 46355 | E7: 75 | F7: =COUNTIF('Tool Map'!$B:$B,A7) -> 11 | G7: =COUNTIFS('Tool Map'!$B:$B,A7,'Tool Map'!$I:$I,"Done") -> 0 | H7: =COUNTIFS('Tool Map'!$B:$B,A7,'Tool Map'!$I:$I,"In progress") -> 0 | I7: =IF(F7=0,0,G7/F7) -> 0
A8: P3 | B8: Verification depth (front-end) | C8: 46356 | D8: 46376 | E8: 75 | F8: =COUNTIF('Tool Map'!$B:$B,A8) -> 12 | G8: =COUNTIFS('Tool Map'!$B:$B,A8,'Tool Map'!$I:$I,"Done") -> 0 | H8: =COUNTIFS('Tool Map'!$B:$B,A8,'Tool Map'!$I:$I,"In progress") -> 0 | I8: =IF(F8=0,0,G8/F8) -> 0
A9: P4 | B9: Front-end closure and docs | C9: 46377 | D9: 46390 | E9: 40 | F9: =COUNTIF('Tool Map'!$B:$B,A9) -> 8 | G9: =COUNTIFS('Tool Map'!$B:$B,A9,'Tool Map'!$I:$I,"Done") -> 0 | H9: =COUNTIFS('Tool Map'!$B:$B,A9,'Tool Map'!$I:$I,"In progress") -> 0 | I9: =IF(F9=0,0,G9/F9) -> 0
A10: P5 | B10: Back-end: place-and-route, sign-off and submission | C10: 46391 | D10: 46405 | E10: 50 | F10: =COUNTIF('Tool Map'!$B:$B,A10) -> 14 | G10: =COUNTIFS('Tool Map'!$B:$B,A10,'Tool Map'!$I:$I,"Done") -> 0 | H10: =COUNTIFS('Tool Map'!$B:$B,A10,'Tool Map'!$I:$I,"In progress") -> 0 | I10: =IF(F10=0,0,G10/F10) -> 0
A11: Total | E11: =SUM(E5:E10) -> 365 | F11: =SUM(F5:F10) -> 68 | G11: =SUM(G5:G10) -> 0 | H11: =SUM(H5:H10) -> 0 | I11: =IF(F11=0,0,G11/F11) -> 0
A13: Notes
A14: Revision 3: front-end only in P0. Tiny Tapeout IHP synthesis (flow setup, tile size, first synthesis, area baseline) moves to P1 and is re-run for area in P2 and P3. Place-and-route, timing sign-off, DRC/LVS, gate-level smoke tests and GDS stay in P5. See the Moved Items sheet.
A15: Source: solo schedule (25 h/week assumption). Hours and dates are planning values and are editable; they were not re-balanced. P1 gains about 8 to 10 hours of synthesis setup work, so consider adding hours to P1.
A16: RISK: place-and-route and timing are still first measured in P5. Synthesis gives an early area signal but not timing or routability.
A17: Whether Verilator 5.052 handles the IHP cell models, SVA, covergroups and the register model is unconfirmed; the P0 UVM spike (UVM-047) covers all but the cell models, which P1 checks.
A18: GitHub and GitHub Actions are not open source; the plan uses Forgejo with Forgejo Actions, or Woodpecker CI.
A19: (stretch) = only if the previous phase finished on time.

Sheet Tool Map
A1: ID | B1: Phase | C1: Dates | D1: Work item | E1: Requirement IDs | F1: Tools | G1: How the tool is used | H1: Owner | I1: Status | J1: Notes
A2: P0-01 | B2: P0 | C2: =TEXT(INDEX(Phases!$C$5:$C$10,MATCH(B2,Phases!$A$5:$A$10,0)),"mm-dd")&" to "&TEXT(INDEX(Phases!$D$5:$D$10,MATCH(B2,Phases!$A$5:$A$10,0)),"mm-dd") -> 10-05 to 10-18 | D2: Create the repo and baselines | E2: OSS-001, CHG-030 | F2: Git | G2: Repo, branches, tags such as base-isa-v0.1 | H2: Me | I2: Not started
A3: P0-02 | B3: P0 | C3: =TEXT(INDEX(Phases!$C$5:$C$10,MATCH(B3,Phases!$A$5:$A$10,0)),"mm-dd")&" to "&TEXT(INDEX(Phases!$D$5:$D$10,MATCH(B3,Phases!$A$5:$A$10,0)),"mm-dd") -> 10-05 to 10-18 | D3: Reproducible front-end toolchain | E3: UVM-049 | F3: Docker (or Nix) | G3: Container pinning the front-end tools; synthesis tools added in P1, place-and-route and sign-off tools in P5 | H3: Me | I3: Not started
A4: P0-03 | B4: P0 | C4: =TEXT(INDEX(Phases!$C$5:$C$10,MATCH(B4,Phases!$A$5:$A$10,0)),"mm-dd")&" to "&TEXT(INDEX(Phases!$D$5:$D$10,MATCH(B4,Phases!$A$5:$A$10,0)),"mm-dd") -> 10-05 to 10-18 | D4: Commit-time checks | E4: NET-051, CHG-004 | F4: pre-commit, Verible, Python | G4: Naming lint; block commits that lack a CR ID | H4: Me | I4: Not started
A5: P0-04 | B5: P0 | C5: =TEXT(INDEX(Phases!$C$5:$C$10,MATCH(B5,Phases!$A$5:$A$10,0)),"mm-dd")&" to "&TEXT(INDEX(Phases!$D$5:$D$10,MATCH(B5,Phases!$A$5:$A$10,0)),"mm-dd") -> 10-05 to 10-18 | D5: Freeze the ISA spec | E5: ISA-018 | F5: Python, PyYAML | G5: Validate isa.yaml (opcode overlaps, field widths) | H5: Me | I5: Not started
A6: P0-05 | B6: P0 | C6: =TEXT(INDEX(Phases!$C$5:$C$10,MATCH(B6,Phases!$A$5:$A$10,0)),"mm-dd")&" to "&TEXT(INDEX(Phases!$D$5:$D$10,MATCH(B6,Phases!$A$5:$A$10,0)),"mm-dd") -> 10-05 to 10-18 | D6: Freeze the register map | E6: HIF-010 | F6: Python, PyYAML, Jinja2 | G6: Validate regmap.yaml; generate first register table | H6: Me | I6: Not started
A7: P0-06 | B7: P0 | C7: =TEXT(INDEX(Phases!$C$5:$C$10,MATCH(B7,Phases!$A$5:$A$10,0)),"mm-dd")&" to "&TEXT(INDEX(Phases!$D$5:$D$10,MATCH(B7,Phases!$A$5:$A$10,0)),"mm-dd") -> 10-05 to 10-18 | D7: Lint the RTL | E7: RTL-005 | F7: Verilator, Verible | G7: Verilator --lint-only -Wall; zero-warning rule from day one | H7: Me | I7: Not started
A8: P0-07 | B8: P0 | C8: =TEXT(INDEX(Phases!$C$5:$C$10,MATCH(B8,Phases!$A$5:$A$10,0)),"mm-dd")&" to "&TEXT(INDEX(Phases!$D$5:$D$10,MATCH(B8,Phases!$A$5:$A$10,0)),"mm-dd") -> 10-05 to 10-18 | D8: UVM spike | E8: UVM-047 | F8: Verilator, Z3, UVM library, GCC | G8: Tiny UVM test: virtual-interface agent, randomize() with {}, covergroup with cross, register model, DPI-C, bound SVA module | H8: Me | I8: Not started
A9: P0-08 | B9: P0 | C9: =TEXT(INDEX(Phases!$C$5:$C$10,MATCH(B9,Phases!$A$5:$A$10,0)),"mm-dd")&" to "&TEXT(INDEX(Phases!$D$5:$D$10,MATCH(B9,Phases!$A$5:$A$10,0)),"mm-dd") -> 10-05 to 10-18 | D9: Draft the module specs | E9: ARC-011, SPC-001 | F9: Pandoc | G9: Section-based spec skeletons following the spec policy | H9: Me | I9: Not started
A10: P0-09 | B10: P0 | C10: =TEXT(INDEX(Phases!$C$5:$C$10,MATCH(B10,Phases!$A$5:$A$10,0)),"mm-dd")&" to "&TEXT(INDEX(Phases!$D$5:$D$10,MATCH(B10,Phases!$A$5:$A$10,0)),"mm-dd") -> 10-05 to 10-18 | D10: Waveform viewing | F10: GTKWave, Surfer | G10: View spike output | H10: Me | I10: Not started
A11: P1-01 | B11: P1 | C11: =TEXT(INDEX(Phases!$C$5:$C$10,MATCH(B11,Phases!$A$5:$A$10,0)),"mm-dd")&" to "&TEXT(INDEX(Phases!$D$5:$D$10,MATCH(B11,Phases!$A$5:$A$10,0)),"mm-dd") -> 10-19 to 11-08 | D11: Lane datapath, decode, imem, I/O synchronizer | E11: ARC-001, ARC-002, ISA-001 to 010, IO-005 | F11: Verilator, Verible | G11: Write and lint the RTL | H11: Me | I11: Not started
A12: P1-02 | B12: P1 | C12: =TEXT(INDEX(Phases!$C$5:$C$10,MATCH(B12,Phases!$A$5:$A$10,0)),"mm-dd")&" to "&TEXT(INDEX(Phases!$D$5:$D$10,MATCH(B12,Phases!$A$5:$A$10,0)),"mm-dd") -> 10-19 to 11-08 | D12: Assembler | E12: SW-001 | F12: Python, pytest | G12: Text-to-binary assembler driven by isa.yaml; unit test per opcode | H12: Me | I12: Not started
A13: P1-03 | B13: P1 | C13: =TEXT(INDEX(Phases!$C$5:$C$10,MATCH(B13,Phases!$A$5:$A$10,0)),"mm-dd")&" to "&TEXT(INDEX(Phases!$D$5:$D$10,MATCH(B13,Phases!$A$5:$A$10,0)),"mm-dd") -> 10-19 to 11-08 | D13: Cycle-accurate ISS | E13: SW-003, DIF-007 | F13: GCC, CMake | G13: Reference model matching the RTL cycle for cycle | H13: Me | I13: Not started
A14: P1-04 | B14: P1 | C14: =TEXT(INDEX(Phases!$C$5:$C$10,MATCH(B14,Phases!$A$5:$A$10,0)),"mm-dd")&" to "&TEXT(INDEX(Phases!$D$5:$D$10,MATCH(B14,Phases!$A$5:$A$10,0)),"mm-dd") -> 10-19 to 11-08 | D14: ISS pin waveforms | E14: SW-003 | F14: GCC, GTKWave, Surfer | G14: ISS writes VCD; view expected pin timing | H14: Me | I14: Not started
A15: P1-05 | B15: P1 | C15: =TEXT(INDEX(Phases!$C$5:$C$10,MATCH(B15,Phases!$A$5:$A$10,0)),"mm-dd")&" to "&TEXT(INDEX(Phases!$D$5:$D$10,MATCH(B15,Phases!$A$5:$A$10,0)),"mm-dd") -> 10-19 to 11-08 | D15: UVM skeleton | E15: UVM-001 to 006 | F15: Verilator, UVM library | G15: Environment, interfaces, config, logging (--timing --binary) | H15: Me | I15: Not started
A16: P1-06 | B16: P1 | C16: =TEXT(INDEX(Phases!$C$5:$C$10,MATCH(B16,Phases!$A$5:$A$10,0)),"mm-dd")&" to "&TEXT(INDEX(Phases!$D$5:$D$10,MATCH(B16,Phases!$A$5:$A$10,0)),"mm-dd") -> 10-19 to 11-08 | D16: SPI host agent and pin agent | E16: UVM-007, UVM-008 | F16: Verilator, UVM library | G16: Driver, monitor, sequences | H16: Me | I16: Not started
A17: P1-07 | B17: P1 | C17: =TEXT(INDEX(Phases!$C$5:$C$10,MATCH(B17,Phases!$A$5:$A$10,0)),"mm-dd")&" to "&TEXT(INDEX(Phases!$D$5:$D$10,MATCH(B17,Phases!$A$5:$A$10,0)),"mm-dd") -> 10-19 to 11-08 | D17: UART partner agent and UART firmware | E17: UVM-009, PRO-001 | F17: Verilator, UVM library, Python | G17: Run assembled firmware on the DUT against a UART partner | H17: Me | I17: Not started
A18: P1-08 | B18: P1 | C18: =TEXT(INDEX(Phases!$C$5:$C$10,MATCH(B18,Phases!$A$5:$A$10,0)),"mm-dd")&" to "&TEXT(INDEX(Phases!$D$5:$D$10,MATCH(B18,Phases!$A$5:$A$10,0)),"mm-dd") -> 10-19 to 11-08 | D18: Directed opcode tests | E18: UVM-023 | F18: Verilator, Python | G18: One test per opcode, tracked by seed | H18: Me | I18: Not started
A19: P1-09 | B19: P1 | C19: =TEXT(INDEX(Phases!$C$5:$C$10,MATCH(B19,Phases!$A$5:$A$10,0)),"mm-dd")&" to "&TEXT(INDEX(Phases!$D$5:$D$10,MATCH(B19,Phases!$A$5:$A$10,0)),"mm-dd") -> 10-19 to 11-08 | D19: Smoke regression | E19: UVM-029, UVM-040 | F19: GNU Make, Python, Forgejo, Woodpecker CI | G19: One command and a CI job | H19: Me | I19: Not started
A20: P1-10 | B20: P1 | C20: =TEXT(INDEX(Phases!$C$5:$C$10,MATCH(B20,Phases!$A$5:$A$10,0)),"mm-dd")&" to "&TEXT(INDEX(Phases!$D$5:$D$10,MATCH(B20,Phases!$A$5:$A$10,0)),"mm-dd") -> 10-19 to 11-08 | D20: Timing diagrams for the spec | E20: SPC-014 | F20: WaveDrom | G20: Cycle-by-cycle instruction diagrams | H20: Me | I20: Not started
A21: P1-11 | B21: P1 | C21: =TEXT(INDEX(Phases!$C$5:$C$10,MATCH(B21,Phases!$A$5:$A$10,0)),"mm-dd")&" to "&TEXT(INDEX(Phases!$D$5:$D$10,MATCH(B21,Phases!$A$5:$A$10,0)),"mm-dd") -> 10-19 to 11-08 | D21: Get the Tiny Tapeout IHP flow running (synthesis) | E21: CON-001 | F21: Tiny Tapeout IHP template, LibreLane, Docker | G21: Add synthesis tools to the container; build the unchanged template through synthesis | H21: Me | I21: Not started
A22: P1-12 | B22: P1 | C22: =TEXT(INDEX(Phases!$C$5:$C$10,MATCH(B22,Phases!$A$5:$A$10,0)),"mm-dd")&" to "&TEXT(INDEX(Phases!$D$5:$D$10,MATCH(B22,Phases!$A$5:$A$10,0)),"mm-dd") -> 10-19 to 11-08 | D22: Set the 6x4 tile size | E22: CON-002 | F22: Tiny Tapeout IHP template | G22: Set tile size in info.yaml | H22: Me | I22: Not started
... A44: P3-09 | B44: P3 | C44: =TEXT(INDEX(Phases!$C$5:$C$10,MATCH(B44,Phases!$A$5:$A$10,0)),"mm-dd")&" to "&TEXT(INDEX(Phases!$D$5:$D$10,MATCH(B44,Phases!$A$5:$A$10,0)),"mm-dd") -> 11-30 to 12-20 | D44: JTAG/SWD reference hosts (stretch) | E44: PRO-004, PRO-005 | F44: OpenOCD, pyOCD | G44: Reference hosts to check JTAG/SWD behavior | H44: Me | I44: Not started
A45: P3-10 | B45: P3 | C45: =TEXT(INDEX(Phases!$C$5:$C$10,MATCH(B45,Phases!$A$5:$A$10,0)),"mm-dd")&" to "&TEXT(INDEX(Phases!$D$5:$D$10,MATCH(B45,Phases!$A$5:$A$10,0)),"mm-dd") -> 11-30 to 12-20 | D45: Debug failing seeds | F45: GTKWave, Surfer | G45: Waveforms from failing seeds | H45: Me | I45: Not started
A46: P3-11 | B46: P3 | C46: =TEXT(INDEX(Phases!$C$5:$C$10,MATCH(B46,Phases!$A$5:$A$10,0)),"mm-dd")&" to "&TEXT(INDEX(Phases!$D$5:$D$10,MATCH(B46,Phases!$A$5:$A$10,0)),"mm-dd") -> 11-30 to 12-20 | D46: Re-run synthesis for area (no place-and-route) | E46: PHY-004 | F46: Yosys, LibreLane | G46: Area check after each feature merge | H46: Me | I46: Not started
A47: P3-12 | B47: P3 | C47: =TEXT(INDEX(Phases!$C$5:$C$10,MATCH(B47,Phases!$A$5:$A$10,0)),"mm-dd")&" to "&TEXT(INDEX(Phases!$D$5:$D$10,MATCH(B47,Phases!$A$5:$A$10,0)),"mm-dd") -> 11-30 to 12-20 | D47: MIN profile fallback proven (synthesis only) | E47: PHY-006 | F47: Yosys, LibreLane | G47: Prove the small profile fits if STD does not | H47: Me | I47: Not started
A48: P4-01 | B48: P4 | C48: =TEXT(INDEX(Phases!$C$5:$C$10,MATCH(B48,Phases!$A$5:$A$10,0)),"mm-dd")&" to "&TEXT(INDEX(Phases!$D$5:$D$10,MATCH(B48,Phases!$A$5:$A$10,0)),"mm-dd") -> 12-21 to 01-03 | D48: Coverage holes | E48: UVM-033 | F48: verilator_coverage, Python, Verilator | G48: Find holes, add tests, record exclusions | H48: Me | I48: Not started
A49: P4-02 | B49: P4 | C49: =TEXT(INDEX(Phases!$C$5:$C$10,MATCH(B49,Phases!$A$5:$A$10,0)),"mm-dd")&" to "&TEXT(INDEX(Phases!$D$5:$D$10,MATCH(B49,Phases!$A$5:$A$10,0)),"mm-dd") -> 12-21 to 01-03 | D49: Synthesizable-subset review | E49: RTL-001, RTL-002 | F49: Verible, Verilator | G49: Code review and lint for the Verilog-2005 synthesizable rules; complements the synthesis runs from P1 | H49: Me | I49: Not started
A50: P4-03 | B50: P4 | C50: =TEXT(INDEX(Phases!$C$5:$C$10,MATCH(B50,Phases!$A$5:$A$10,0)),"mm-dd")&" to "&TEXT(INDEX(Phases!$D$5:$D$10,MATCH(B50,Phases!$A$5:$A$10,0)),"mm-dd") -> 12-21 to 01-03 | D50: Front-end freeze and RTL release candidate | E50: CHG-030, CHG-031 | F50: Git, GNU Make | G50: Tag the RTL candidate after full regression | H50: Me | I50: Not started
A51: P4-04 | B51: P4 | C51: =TEXT(INDEX(Phases!$C$5:$C$10,MATCH(B51,Phases!$A$5:$A$10,0)),"mm-dd")&" to "&TEXT(INDEX(Phases!$D$5:$D$10,MATCH(B51,Phases!$A$5:$A$10,0)),"mm-dd") -> 12-21 to 01-03 | D51: Protocol rate table (target clock) | E51: TIM-006 | F51: Python, Jinja2 | G51: Generate from regression results; update with real fmax in P5 | H51: Me | I51: Not started
A52: P4-05 | B52: P4 | C52: =TEXT(INDEX(Phases!$C$5:$C$10,MATCH(B52,Phases!$A$5:$A$10,0)),"mm-dd")&" to "&TEXT(INDEX(Phases!$D$5:$D$10,MATCH(B52,Phases!$A$5:$A$10,0)),"mm-dd") -> 12-21 to 01-03 | D52: Datasheet build (draft) | E52: OSS-002, DSU-003, DSU-022 | F52: Pandoc, Python, Jinja2, WeasyPrint | G52: Generate tables from YAML; CI compares with committed copy | H52: Me | I52: Not started
A53: P4-06 | B53: P4 | C53: =TEXT(INDEX(Phases!$C$5:$C$10,MATCH(B53,Phases!$A$5:$A$10,0)),"mm-dd")&" to "&TEXT(INDEX(Phases!$D$5:$D$10,MATCH(B53,Phases!$A$5:$A$10,0)),"mm-dd") -> 12-21 to 01-03 | D53: Diagrams and timing figures | F53: Graphviz, Mermaid, WaveDrom | G53: Figures | H53: Me | I53: Not started
A54: P4-07 | B54: P4 | C54: =TEXT(INDEX(Phases!$C$5:$C$10,MATCH(B54,Phases!$A$5:$A$10,0)),"mm-dd")&" to "&TEXT(INDEX(Phases!$D$5:$D$10,MATCH(B54,Phases!$A$5:$A$10,0)),"mm-dd") -> 12-21 to 01-03 | D54: Tutorial | E54: OSS-003 | F54: Pandoc, Python | G54: UART in 10 instructions with a runnable example (assembler and ISS) | H54: Me | I54: Not started
A55: P4-08 | B55: P4 | C55: =TEXT(INDEX(Phases!$C$5:$C$10,MATCH(B55,Phases!$A$5:$A$10,0)),"mm-dd")&" to "&TEXT(INDEX(Phases!$D$5:$D$10,MATCH(B55,Phases!$A$5:$A$10,0)),"mm-dd") -> 12-21 to 01-03 | D55: Verification plan sign-off (front-end) | E55: UVM-045 | F55: Python, Git | G55: Trace script checks every requirement has a test | H55: Me | I55: Not started
A56: P5-01 | B56: P5 | C56: =TEXT(INDEX(Phases!$C$5:$C$10,MATCH(B56,Phases!$A$5:$A$10,0)),"mm-dd")&" to "&TEXT(INDEX(Phases!$D$5:$D$10,MATCH(B56,Phases!$A$5:$A$10,0)),"mm-dd") -> 01-04 to 01-18 | D56: Run the full RTL-to-GDS flow with the real RTL | E56: CON-001 | F56: Tiny Tapeout IHP template, LibreLane, Docker | G56: Add place-and-route and sign-off tools to the container; run the full flow | H56: Me | I56: Not started
A57: P5-02 | B57: P5 | C57: =TEXT(INDEX(Phases!$C$5:$C$10,MATCH(B57,Phases!$A$5:$A$10,0)),"mm-dd")&" to "&TEXT(INDEX(Phases!$D$5:$D$10,MATCH(B57,Phases!$A$5:$A$10,0)),"mm-dd") -> 01-04 to 01-18 | D57: RTL fixes from place-and-route findings | E57: CHG-020, CHG-022 | F57: Verilator, Verible, Git | G57: Change requests for timing or congestion problems; rerun regression | H57: Me | I57: Not started
A58: P5-03 | B58: P5 | C58: =TEXT(INDEX(Phases!$C$5:$C$10,MATCH(B58,Phases!$A$5:$A$10,0)),"mm-dd")&" to "&TEXT(INDEX(Phases!$D$5:$D$10,MATCH(B58,Phases!$A$5:$A$10,0)),"mm-dd") -> 01-04 to 01-18 | D58: First place-and-route trial | E58: PHY-002 | F58: LibreLane, OpenROAD, Yosys | G58: Full flow on the 6x4 tile | H58: Me | I58: Not started
A59: P5-04 | B59: P5 | C59: =TEXT(INDEX(Phases!$C$5:$C$10,MATCH(B59,Phases!$A$5:$A$10,0)),"mm-dd")&" to "&TEXT(INDEX(Phases!$D$5:$D$10,MATCH(B59,Phases!$A$5:$A$10,0)),"mm-dd") -> 01-04 to 01-18 | D59: Timing and layout checks | E59: PHY-003 | F59: OpenSTA, KLayout | G59: Slack report and layout inspection | H59: Me | I59: Not started
A60: P5-05 | B60: P5 | C60: =TEXT(INDEX(Phases!$C$5:$C$10,MATCH(B60,Phases!$A$5:$A$10,0)),"mm-dd")&" to "&TEXT(INDEX(Phases!$D$5:$D$10,MATCH(B60,Phases!$A$5:$A$10,0)),"mm-dd") -> 01-04 to 01-18 | D60: Gate-level smoke tests | E60: UVM-038 | F60: Yosys, LibreLane, Verilator, IHP PDK cell models | G60: Zero-delay functional run of gls_smoke; timing comes from STA | H60: Me | I60: Not started
A61: P5-06 | B61: P5 | C61: =TEXT(INDEX(Phases!$C$5:$C$10,MATCH(B61,Phases!$A$5:$A$10,0)),"mm-dd")&" to "&TEXT(INDEX(Phases!$D$5:$D$10,MATCH(B61,Phases!$A$5:$A$10,0)),"mm-dd") -> 01-04 to 01-18 | D61: Timing sign-off | E61: PHY-003 | F61: OpenSTA | G61: Setup and hold at the target clock | H61: Me | I61: Not started
...

Sheet Intent
A1: ID | B1: Phase | C1: Work item | D1: Requirement IDs | E1: Intent (why this work item exists)
A2: P0-01 | B2: P0 | C2: =INDEX('Tool Map'!$D:$D,MATCH($A2,'Tool Map'!$A:$A,0)) -> Create the repo and baselines | D2: =IF(INDEX('Tool Map'!$E:$E,MATCH($A2,'Tool Map'!$A:$A,0))="","-",INDEX('Tool Map'!$E:$E,MATCH($A2,'Tool Map'!$A:$A,0))) -> OSS-001, CHG-030 | E2: Create one traceable source of truth so every change, baseline and release can be reproduced and audited.
A3: P0-02 | B3: P0 | C3: =INDEX('Tool Map'!$D:$D,MATCH($A3,'Tool Map'!$A:$A,0)) -> Reproducible front-end toolchain | D3: =IF(INDEX('Tool Map'!$E:$E,MATCH($A3,'Tool Map'!$A:$A,0))="","-",INDEX('Tool Map'!$E:$E,MATCH($A3,'Tool Map'!$A:$A,0))) -> UVM-049 | E3: Make every build and simulation reproducible with identical tool versions, so results do not depend on the machine.
A4: P0-03 | B4: P0 | C4: =INDEX('Tool Map'!$D:$D,MATCH($A4,'Tool Map'!$A:$A,0)) -> Commit-time checks | D4: =IF(INDEX('Tool Map'!$E:$E,MATCH($A4,'Tool Map'!$A:$A,0))="","-",INDEX('Tool Map'!$E:$E,MATCH($A4,'Tool Map'!$A:$A,0))) -> NET-051, CHG-004 | E4: Catch naming and change-control violations at commit time, when they are cheapest to fix.
A5: P0-04 | B5: P0 | C5: =INDEX('Tool Map'!$D:$D,MATCH($A5,'Tool Map'!$A:$A,0)) -> Freeze the ISA spec | D5: =IF(INDEX('Tool Map'!$E:$E,MATCH($A5,'Tool Map'!$A:$A,0))="","-",INDEX('Tool Map'!$E:$E,MATCH($A5,'Tool Map'!$A:$A,0))) -> ISA-018 | E5: Fix the instruction set as one machine-readable contract so the RTL, assembler, simulator and tests cannot drift apart.
A6: P0-05 | B6: P0 | C6: =INDEX('Tool Map'!$D:$D,MATCH($A6,'Tool Map'!$A:$A,0)) -> Freeze the register map | D6: =IF(INDEX('Tool Map'!$E:$E,MATCH($A6,'Tool Map'!$A:$A,0))="","-",INDEX('Tool Map'!$E:$E,MATCH($A6,'Tool Map'!$A:$A,0))) -> HIF-010 | E6: Fix the host-visible register contract early so RTL, register model, firmware library and datasheet come from one source.
A7: P0-06 | B7: P0 | C7: =INDEX('Tool Map'!$D:$D,MATCH($A7,'Tool Map'!$A:$A,0)) -> Lint the RTL | D7: =IF(INDEX('Tool Map'!$E:$E,MATCH($A7,'Tool Map'!$A:$A,0))="","-",INDEX('Tool Map'!$E:$E,MATCH($A7,'Tool Map'!$A:$A,0))) -> RTL-005 | E7: Keep the RTL clean and synthesizable from the first line instead of cleaning up a pile of warnings later.
A8: P0-07 | B8: P0 | C8: =INDEX('Tool Map'!$D:$D,MATCH($A8,'Tool Map'!$A:$A,0)) -> UVM spike | D8: =IF(INDEX('Tool Map'!$E:$E,MATCH($A8,'Tool Map'!$A:$A,0))="","-",INDEX('Tool Map'!$E:$E,MATCH($A8,'Tool Map'!$A:$A,0))) -> UVM-047 | E8: Learn in hours, not weeks, whether Verilator 5.052 can run the planned UVM environment, and choose the fallback early if not.
A9: P0-08 | B9: P0 | C9: =INDEX('Tool Map'!$D:$D,MATCH($A9,'Tool Map'!$A:$A,0)) -> Draft the module specs | D9: =IF(INDEX('Tool Map'!$E:$E,MATCH($A9,'Tool Map'!$A:$A,0))="","-",INDEX('Tool Map'!$E:$E,MATCH($A9,'Tool Map'!$A:$A,0))) -> ARC-011, SPC-001 | E9: Write down each block's intended behavior before coding so implementation and tests have a reference and design errors surface in review.
A10: P0-09 | B10: P0 | C10: =INDEX('Tool Map'!$D:$D,MATCH($A10,'Tool Map'!$A:$A,0)) -> Waveform viewing | D10: =IF(INDEX('Tool Map'!$E:$E,MATCH($A10,'Tool Map'!$A:$A,0))="","-",INDEX('Tool Map'!$E:$E,MATCH($A10,'Tool Map'!$A:$A,0))) -> - | E10: Confirm waveform debugging works from the start so failures can be inspected without delay.
A11: P1-01 | B11: P1 | C11: =INDEX('Tool Map'!$D:$D,MATCH($A11,'Tool Map'!$A:$A,0)) -> Lane datapath, decode, imem, I/O synchronizer | D11: =IF(INDEX('Tool Map'!$E:$E,MATCH($A11,'Tool Map'!$A:$A,0))="","-",INDEX('Tool Map'!$E:$E,MATCH($A11,'Tool Map'!$A:$A,0))) -> ARC-001, ARC-002, ISA-001 to 010, IO-005 | E11: Build the core lane engine that executes instructions in deterministic single cycles, the foundation everything else depends on.
A12: P1-02 | B12: P1 | C12: =INDEX('Tool Map'!$D:$D,MATCH($A12,'Tool Map'!$A:$A,0)) -> Assembler | D12: =IF(INDEX('Tool Map'!$E:$E,MATCH($A12,'Tool Map'!$A:$A,0))="","-",INDEX('Tool Map'!$E:$E,MATCH($A12,'Tool Map'!$A:$A,0))) -> SW-001 | E12: Let firmware be written as text and turned into the exact binary the chip runs, so protocols are developed without hand-encoding opcodes.
A13: P1-03 | B13: P1 | C13: =INDEX('Tool Map'!$D:$D,MATCH($A13,'Tool Map'!$A:$A,0)) -> Cycle-accurate ISS | D13: =IF(INDEX('Tool Map'!$E:$E,MATCH($A13,'Tool Map'!$A:$A,0))="","-",INDEX('Tool Map'!$E:$E,MATCH($A13,'Tool Map'!$A:$A,0))) -> SW-003, DIF-007 | E13: Provide a cycle-accurate golden reference of what a lane should do, used for firmware development and as the scoreboard reference.
... A69: P5-14 | B69: P5 | C69: =INDEX('Tool Map'!$D:$D,MATCH($A69,'Tool Map'!$A:$A,0)) -> Submission package | D69: =IF(INDEX('Tool Map'!$E:$E,MATCH($A69,'Tool Map'!$A:$A,0))="","-",INDEX('Tool Map'!$E:$E,MATCH($A69,'Tool Map'!$A:$A,0))) -> CON-006 | E69: Deliver a complete, reproducible, open-source submission by the deadline.

Sheet Tools
A1: Tool | B1: Category | C1: P0 | D1: P1 | E1: P2 | F1: P3 | G1: P4 | H1: P5 | I1: Total work items | J1: Match text
A2: Git | B2: Version control | C2: =COUNTIFS('Tool Map'!$B:$B,"P0",'Tool Map'!$F:$F,"*"&$J2&"*") -> 1 | D2: =COUNTIFS('Tool Map'!$B:$B,"P1",'Tool Map'!$F:$F,"*"&$J2&"*") -> 0 | E2: =COUNTIFS('Tool Map'!$B:$B,"P2",'Tool Map'!$F:$F,"*"&$J2&"*") -> 0 | F2: =COUNTIFS('Tool Map'!$B:$B,"P3",'Tool Map'!$F:$F,"*"&$J2&"*") -> 0 | G2: =COUNTIFS('Tool Map'!$B:$B,"P4",'Tool Map'!$F:$F,"*"&$J2&"*") -> 2 | H2: =COUNTIFS('Tool Map'!$B:$B,"P5",'Tool Map'!$F:$F,"*"&$J2&"*") -> 3 | I2: =SUM(C2:H2) -> 6 | J2: Git
A3: Docker (or Nix) | B3: Environment | C3: =COUNTIFS('Tool Map'!$B:$B,"P0",'Tool Map'!$F:$F,"*"&$J3&"*") -> 1 | D3: =COUNTIFS('Tool Map'!$B:$B,"P1",'Tool Map'!$F:$F,"*"&$J3&"*") -> 1 | E3: =COUNTIFS('Tool Map'!$B:$B,"P2",'Tool Map'!$F:$F,"*"&$J3&"*") -> 0 | F3: =COUNTIFS('Tool Map'!$B:$B,"P3",'Tool Map'!$F:$F,"*"&$J3&"*") -> 0 | G3: =COUNTIFS('Tool Map'!$B:$B,"P4",'Tool Map'!$F:$F,"*"&$J3&"*") -> 0 | H3: =COUNTIFS('Tool Map'!$B:$B,"P5",'Tool Map'!$F:$F,"*"&$J3&"*") -> 1 | I3: =SUM(C3:H3) -> 3 | J3: Docker
A4: Tiny Tapeout IHP template | B4: Physical flow | C4: =COUNTIFS('Tool Map'!$B:$B,"P0",'Tool Map'!$F:$F,"*"&$J4&"*") -> 0 | D4: =COUNTIFS('Tool Map'!$B:$B,"P1",'Tool Map'!$F:$F,"*"&$J4&"*") -> 2 | E4: =COUNTIFS('Tool Map'!$B:$B,"P2",'Tool Map'!$F:$F,"*"&$J4&"*") -> 0 | F4: =COUNTIFS('Tool Map'!$B:$B,"P3",'Tool Map'!$F:$F,"*"&$J4&"*") -> 0 | G4: =COUNTIFS('Tool Map'!$B:$B,"P4",'Tool Map'!$F:$F,"*"&$J4&"*") -> 0 | H4: =COUNTIFS('Tool Map'!$B:$B,"P5",'Tool Map'!$F:$F,"*"&$J4&"*") -> 2 | I4: =SUM(C4:H4) -> 4 | J4: Tiny Tapeout IHP template
A5: LibreLane | B5: Physical flow | C5: =COUNTIFS('Tool Map'!$B:$B,"P0",'Tool Map'!$F:$F,"*"&$J5&"*") -> 0 | D5: =COUNTIFS('Tool Map'!$B:$B,"P1",'Tool Map'!$F:$F,"*"&$J5&"*") -> 2 | E5: =COUNTIFS('Tool Map'!$B:$B,"P2",'Tool Map'!$F:$F,"*"&$J5&"*") -> 1 | F5: =COUNTIFS('Tool Map'!$B:$B,"P3",'Tool Map'!$F:$F,"*"&$J5&"*") -> 2 | G5: =COUNTIFS('Tool Map'!$B:$B,"P4",'Tool Map'!$F:$F,"*"&$J5&"*") -> 0 | H5: =COUNTIFS('Tool Map'!$B:$B,"P5",'Tool Map'!$F:$F,"*"&$J5&"*") -> 6 | I5: =SUM(C5:H5) -> 11 | J5: LibreLane
A6: Yosys | B6: Synthesis | C6: =COUNTIFS('Tool Map'!$B:$B,"P0",'Tool Map'!$F:$F,"*"&$J6&"*") -> 0 | D6: =COUNTIFS('Tool Map'!$B:$B,"P1",'Tool Map'!$F:$F,"*"&$J6&"*") -> 2 | E6: =COUNTIFS('Tool Map'!$B:$B,"P2",'Tool Map'!$F:$F,"*"&$J6&"*") -> 1 | F6: =COUNTIFS('Tool Map'!$B:$B,"P3",'Tool Map'!$F:$F,"*"&$J6&"*") -> 3 | G6: =COUNTIFS('Tool Map'!$B:$B,"P4",'Tool Map'!$F:$F,"*"&$J6&"*") -> 0 | H6: =COUNTIFS('Tool Map'!$B:$B,"P5",'Tool Map'!$F:$F,"*"&$J6&"*") -> 3 | I6: =SUM(C6:H6) -> 9 | J6: Yosys
A7: OpenROAD | B7: Physical flow | C7: =COUNTIFS('Tool Map'!$B:$B,"P0",'Tool Map'!$F:$F,"*"&$J7&"*") -> 0 | D7: =COUNTIFS('Tool Map'!$B:$B,"P1",'Tool Map'!$F:$F,"*"&$J7&"*") -> 0 | E7: =COUNTIFS('Tool Map'!$B:$B,"P2",'Tool Map'!$F:$F,"*"&$J7&"*") -> 0 | F7: =COUNTIFS('Tool Map'!$B:$B,"P3",'Tool Map'!$F:$F,"*"&$J7&"*") -> 0 | G7: =COUNTIFS('Tool Map'!$B:$B,"P4",'Tool Map'!$F:$F,"*"&$J7&"*") -> 0 | H7: =COUNTIFS('Tool Map'!$B:$B,"P5",'Tool Map'!$F:$F,"*"&$J7&"*") -> 3 | I7: =SUM(C7:H7) -> 3 | J7: OpenROAD
A8: OpenSTA | B8: Timing | C8: =COUNTIFS('Tool Map'!$B:$B,"P0",'Tool Map'!$F:$F,"*"&$J8&"*") -> 0 | D8: =COUNTIFS('Tool Map'!$B:$B,"P1",'Tool Map'!$F:$F,"*"&$J8&"*") -> 0 | E8: =COUNTIFS('Tool Map'!$B:$B,"P2",'Tool Map'!$F:$F,"*"&$J8&"*") -> 0 | F8: =COUNTIFS('Tool Map'!$B:$B,"P3",'Tool Map'!$F:$F,"*"&$J8&"*") -> 0 | G8: =COUNTIFS('Tool Map'!$B:$B,"P4",'Tool Map'!$F:$F,"*"&$J8&"*") -> 0 | H8: =COUNTIFS('Tool Map'!$B:$B,"P5",'Tool Map'!$F:$F,"*"&$J8&"*") -> 2 | I8: =SUM(C8:H8) -> 2 | J8: OpenSTA
A9: KLayout | B9: Layout / DRC / LVS | C9: =COUNTIFS('Tool Map'!$B:$B,"P0",'Tool Map'!$F:$F,"*"&$J9&"*") -> 0 | D9: =COUNTIFS('Tool Map'!$B:$B,"P1",'Tool Map'!$F:$F,"*"&$J9&"*") -> 0 | E9: =COUNTIFS('Tool Map'!$B:$B,"P2",'Tool Map'!$F:$F,"*"&$J9&"*") -> 0 | F9: =COUNTIFS('Tool Map'!$B:$B,"P3",'Tool Map'!$F:$F,"*"&$J9&"*") -> 0 | G9: =COUNTIFS('Tool Map'!$B:$B,"P4",'Tool Map'!$F:$F,"*"&$J9&"*") -> 0 | H9: =COUNTIFS('Tool Map'!$B:$B,"P5",'Tool Map'!$F:$F,"*"&$J9&"*") -> 3 | I9: =SUM(C9:H9) -> 3 | J9: KLayout
A10: Magic | B10: Layout / DRC | C10: =COUNTIFS('Tool Map'!$B:$B,"P0",'Tool Map'!$F:$F,"*"&$J10&"*") -> 0 | D10: =COUNTIFS('Tool Map'!$B:$B,"P1",'Tool Map'!$F:$F,"*"&$J10&"*") -> 0 | E10: =COUNTIFS('Tool Map'!$B:$B,"P2",'Tool Map'!$F:$F,"*"&$J10&"*") -> 0 | F10: =COUNTIFS('Tool Map'!$B:$B,"P3",'Tool Map'!$F:$F,"*"&$J10&"*") -> 0 | G10: =COUNTIFS('Tool Map'!$B:$B,"P4",'Tool Map'!$F:$F,"*"&$J10&"*") -> 0 | H10: =COUNTIFS('Tool Map'!$B:$B,"P5",'Tool Map'!$F:$F,"*"&$J10&"*") -> 1 | I10: =SUM(C10:H10) -> 1 | J10: Magic
A11: Netgen | B11: LVS | C11: =COUNTIFS('Tool Map'!$B:$B,"P0",'Tool Map'!$F:$F,"*"&$J11&"*") -> 0 | D11: =COUNTIFS('Tool Map'!$B:$B,"P1",'Tool Map'!$F:$F,"*"&$J11&"*") -> 0 | E11: =COUNTIFS('Tool Map'!$B:$B,"P2",'Tool Map'!$F:$F,"*"&$J11&"*") -> 0 | F11: =COUNTIFS('Tool Map'!$B:$B,"P3",'Tool Map'!$F:$F,"*"&$J11&"*") -> 0 | G11: =COUNTIFS('Tool Map'!$B:$B,"P4",'Tool Map'!$F:$F,"*"&$J11&"*") -> 0 | H11: =COUNTIFS('Tool Map'!$B:$B,"P5",'Tool Map'!$F:$F,"*"&$J11&"*") -> 1 | I11: =SUM(C11:H11) -> 1 | J11: Netgen
A12: IHP PDK cell models | B12: PDK | C12: =COUNTIFS('Tool Map'!$B:$B,"P0",'Tool Map'!$F:$F,"*"&$J12&"*") -> 0 | D12: =COUNTIFS('Tool Map'!$B:$B,"P1",'Tool Map'!$F:$F,"*"&$J12&"*") -> 1 | E12: =COUNTIFS('Tool Map'!$B:$B,"P2",'Tool Map'!$F:$F,"*"&$J12&"*") -> 0 | F12: =COUNTIFS('Tool Map'!$B:$B,"P3",'Tool Map'!$F:$F,"*"&$J12&"*") -> 0 | G12: =COUNTIFS('Tool Map'!$B:$B,"P4",'Tool Map'!$F:$F,"*"&$J12&"*") -> 0 | H12: =COUNTIFS('Tool Map'!$B:$B,"P5",'Tool Map'!$F:$F,"*"&$J12&"*") -> 1 | I12: =SUM(C12:H12) -> 2 | J12: IHP PDK cell models
A13: Verilator | B13: Simulation / lint / coverage | C13: =COUNTIFS('Tool Map'!$B:$B,"P0",'Tool Map'!$F:$F,"*"&$J13&"*") -> 2 | D13: =COUNTIFS('Tool Map'!$B:$B,"P1",'Tool Map'!$F:$F,"*"&$J13&"*") -> 6 | E13: =COUNTIFS('Tool Map'!$B:$B,"P2",'Tool Map'!$F:$F,"*"&$J13&"*") -> 6 | F13: =COUNTIFS('Tool Map'!$B:$B,"P3",'Tool Map'!$F:$F,"*"&$J13&"*") -> 7 | G13: =COUNTIFS('Tool Map'!$B:$B,"P4",'Tool Map'!$F:$F,"*"&$J13&"*") -> 2 | H13: =COUNTIFS('Tool Map'!$B:$B,"P5",'Tool Map'!$F:$F,"*"&$J13&"*") -> 2 | I13: =SUM(C13:H13) -> 25 | J13: Verilator
... A37: pyOCD | B37: Stretch protocols | C37: =COUNTIFS('Tool Map'!$B:$B,"P0",'Tool Map'!$F:$F,"*"&$J37&"*") -> 0 | D37: =COUNTIFS('Tool Map'!$B:$B,"P1",'Tool Map'!$F:$F,"*"&$J37&"*") -> 0 | E37: =COUNTIFS('Tool Map'!$B:$B,"P2",'Tool Map'!$F:$F,"*"&$J37&"*") -> 0 | F37: =COUNTIFS('Tool Map'!$B:$B,"P3",'Tool Map'!$F:$F,"*"&$J37&"*") -> 1 | G37: =COUNTIFS('Tool Map'!$B:$B,"P4",'Tool Map'!$F:$F,"*"&$J37&"*") -> 0 | H37: =COUNTIFS('Tool Map'!$B:$B,"P5",'Tool Map'!$F:$F,"*"&$J37&"*") -> 0 | I37: =SUM(C37:H37) -> 1 | J37: pyOCD
A39: Counts are the number of Tool Map work items whose Tools cell mentions the tool (text match). Yosys also matches SymbiYosys, and Verilator also matches verilator_coverage.

Sheet Moved Items
A1: Item | B1: Requirement IDs | C1: v1 plan | D1: v2 plan | E1: v3 plan (now) | F1: Effect / mitigation
A2: Tiny Tapeout flow running | B2: CON-001 | C2: P0 | D2: P5 | E2: P1 | F2: Template built through synthesis in P1; full flow with real RTL in P5
A3: Set 6x4 tile size | B3: CON-002 | C3: P0 | D3: P5 | E3: P1 | F3: Low risk
A4: First synthesis and area baseline | B4: PHY-004, CON-004 | C4: P0 | D4: P5 | E4: P1 | F4: Early area signal on the single-lane core
A5: Gate-level cell-model feasibility check | B5: UVM-038 | C5: P0 | D5: P5 | E5: P1 | F5: Elaborate the synthesized netlist and cell models in Verilator; result decides whether gate-level smoke tests in P5 are possible
A6: Re-run synthesis for area at each merge | B6: PHY-004 | C6: P1 to P3 | D6: P5 | E6: P2 and P3 | F6: Yosys and LibreLane synthesis only, no place-and-route
A7: MIN profile fallback proven | B7: PHY-006 | C7: P3 | D7: P5 | E7: P3 | F7: Synthesis only; routability still unknown
A8: First place-and-route trial | B8: PHY-002 | C8: P2 | D8: P5 | E8: P5 | F8: Routing congestion found late
A9: Timing and layout checks | B9: PHY-003 | C9: P2 | D9: P5 | E9: P5 | F9: Fmax unknown until P5; rate table in P4 uses the target clock
A10: Gate-level smoke tests, timing sign-off, area check, DRC, LVS, final GDS | B10: UVM-038, PHY-001 to 003 | C10: P4 | D10: P5 | E10: P5 | F10: P5 carries all place-and-route and sign-off closure
A11: Datasheet build, figures, tutorial, vPlan sign-off | B11: OSS-002, OSS-003, UVM-045 | C11: P5 | D11: P4 | E11: P4 | F11: Moved earlier to free P5; datasheet numbers updated in P5
A12: Power estimate (stretch) | B12: PHY-005 | C12: P5 | D12: P5 | E12: P5 | F12: Unchanged
A14: Process note: moving milestone scope and revising PHY-004 and PHY-006 are Major changes under the development policies (CHG-002, CHG-031). Raise a CR and observe the 24-hour cooling-off.
A15: Mitigation options if P5 looks too tight: (1) move the front-end freeze earlier, e.g. 12-13, and start P5 on 12-14; (2) run one early place-and-route trial after the P1 synthesis as a go/no-go check (about 2 to 3 hours); (3) pre-agree the MIN profile as the submission fallback.
